Workbook

Sheet Svarene #1
A1: Sæt virksomheds svar på spørgeskemaet #1 ind i tabellen nedenfor (0 - ved ikke/slet ikke, 1 - i mindre grad, 2 - i noget grad, 3 - i høj grad, 4 - i meget høj grad).
B3: #1 | C3: #2 | D3: #3 | E3: #4 | F3: #5
B4: [indsæt medarbejders navn/titel] | C4: [indsæt medarbejders navn/titel] | D4: [indsæt medarbejders navn/titel] | E4: [indsæt medarbejders navn/titel] | F4: [indsæt medarbejders navn/titel]
A5: 1. Vi har medarbejdere med viden om bæredygtig udvikling | B5: 4 | C5: 3 | D5: 3 | E5: 3 | F5: 3 | K5: Forklaring
A6: 2. Vi har en plan for at udvikle medarbejdernes viden og kompetencer mht. bæredygtighed og cirkulær økonomi | B6: 1 | C6: 3 | D6: 2 | E6: 2 | F6: 1 | K6: gul | L6: skal redigeres
A7: 3. Vi anser den grønne omstilling for en mulighed frem for en trussel | B7: 4 | C7: 4 | D7: 0 | E7: 3 | F7: 3 | K7: orange | L7: anvisninger
A8: 4. Både vores ledelse og bestyrelse har fokus på bæredygtighed (f.eks. støtter de initiativer og projekter omkring bæredygtighed og allokerer ressourcer til dem) | B8: 4 | C8: 3 | D8: 3 | E8: 3 | F8: 0
A9: 5. Mindset og kultur i vores organisation er fremadskuende og klar til at følge med den grønne omstilling | B9: 3 | C9: 3 | D9: 2 | E9: 3 | F9: 3
A10: 6. Vi har værktøjer til at vurdere, hvilke effekter vores forretningsbeslutninger har på miljøet og samfundet | B10: 2 | C10: 2 | D10: 0 | E10: 3 | F10: 0
A11: 7. Vores organisation har en klar strategi for at arbejde med bæredygtighed | B11: 3 | C11: 3 | D11: 2 | E11: 3 | F11: 3
A12: 8. Vi har sat tydelige mål mht. bæredygtighed og bruger data og KPIer til at vurdere vores fremskridt | B12: 1 | C12: 2 | D12: 0 | E12: 3 | F12: 0
B13: =AVERAGE(B5:F5)+AVERAGE(B6:F6)+AVERAGE(B7:F7)+AVERAGE(B8:F8)+AVERAGE(B9:F9)+AVERAGE(B10:F10)+AVERAGE(B11:F11)+AVERAGE(B12:F12) -> 18.6
A14: 9. Vi er gode til intern kommunikation og erfaringsudveksling | B14: 3 | C14: 1 | D14: 2 | E14: 3 | F14: 3
A15: 10. Vi har gode kontakter i vores branche udenfor vores egen værdikæde (f.eks. er vi del af brancheorganisationer) | B15: 3 | C15: 2 | D15: 2 | E15: 2 | F15: 0
A16: 11. Vi har god kontakt til virksomheder og andre aktører i vores lokalområde (f.eks. igennem lokale erhvervsnetværk) | B16: 3 | C16: 3 | D16: 2 | E16: 2 | F16: 3
A17: 12. Vi har god kontakt til andre aktører (regeringen, universiteter, samfundsorganisationer og civilsamfundet) | B17: 2 | C17: 2 | D17: 2 | E17: 2 | F17: 1
A18: 13. Vi arbejder sammen med og/eller påvirker vores værdikæde (f.eks. kunder og leverandører) mht. bæredygtighed | B18: 2 | C18: 2 | D18: 1 | E18: 1 | F18: 3
A19: 14. Vi har allerede samarbejdet omkring bæredygtighed med aktørerne nævnt i spørgsmål 10-12 (f.eks. for at muliggøre cirkulære forretningsaktiviteter) | B19: 3 | C19: 2 | D19: 2 | E19: 1 | F19: 3
A20: 15. Vi er åbne for nye partnerskaber omkring bæredygtighed | B20: 4 | C20: 4 | D20: 4 | E20: 3 | F20: 3
A21: 16. Vi er klar til at dele informationer omkring vores forretning (f.eks. mængden af inputs og affaldsmaterialer) med andre organisationer | B21: 3 | C21: 3 | D21: 3 | E21: 3 | F21: 0
B22: =AVERAGE(B14:F14)+AVERAGE(B15:F15)+AVERAGE(B16:F16)+AVERAGE(B17:F17)+AVERAGE(B18:F18)+AVERAGE(B19:F19)+AVERAGE(B20:F20)+AVERAGE(B21:F21) -> 18.6
B24: Score
A25: Total | B25: =B26+B27 -> 37.2 | C25: -> indsæt værdien på side 2 i parathedsrapporten, linje 2
A26: Bæredygtighed | B26: =B13 -> 18.6 | C26: -> indsæt værdien på side 2 i parathedsrapporten, linje 3
A27: Samarbejde | B27: =B22 -> 18.6 | C27: -> indsæt værdien på side 2 i parathedsrapporten, linje 4
A31: Bruges udelukkende for at automatisk generere grafikker i de andre ark.
B32: Highest score | C32: Lowest score | D32: Average
A33: Medarbejdere med viden om bæredygtig udvikling | B33: =MAX(B5:F5) -> 4 | C33: =MIN(B5:F5) -> 3 | D33: =AVERAGE(B5:F5) -> 3.2
A34: Plan for udvikling af viden og kompetencer | B34: =MAX(B6:F6) -> 3 | C34: =MIN(B6:F6) -> 1 | D34: =AVERAGE(B6:F6) -> 1.8
A35: Grønne omstilling som mulighed | B35: =MAX(B7:F7) -> 4 | C35: =MIN(B7:F7) -> 0 | D35: =AVERAGE(B7:F7) -> 2.8
A36: Ledelse og bestyrelse med fokus på bæredygtighed | B36: =MAX(B8:F8) -> 4 | C36: =MIN(B8:F8) -> 0 | D36: =AVERAGE(B8:F8) -> 2.6
A37: Fremadskuende kultur og mindset | B37: =MAX(B9:F9) -> 3 | C37: =MIN(B9:F9) -> 2 | D37: =AVERAGE(B9:F9) -> 2.8
A38: Værtøjer til effektvurdering | B38: =MAX(B10:F10) -> 3 | C38: =MIN(B10:F10) -> 0 | D38: =AVERAGE(B10:F10) -> 1.4
A39: Strategi | B39: =MAX(B11:F11) -> 3 | C39: =MIN(B11:F11) -> 2 | D39: =AVERAGE(B11:F11) -> 2.8
A40: Tydelige mål og KPIer | B40: =MAX(B12:F12) -> 3 | C40: =MIN(B12:F12) -> 0 | D40: =AVERAGE(B12:F12) -> 1.2
A42: Intern kommunikation | B42: =MAX(B14:F14) -> 3 | C42: =MIN(B14:F14) -> 1 | D42: =AVERAGE(B14:F14) -> 2.4
A43: Kontakter i branchen | B43: =MAX(B15:F15) -> 3 | C43: =MIN(B15:F15) -> 0 | D43: =AVERAGE(B15:F15) -> 1.8
A44: Kontakt i lokalområdet | B44: =MAX(B16:F16) -> 3 | C44: =MIN(B16:F16) -> 2 | D44: =AVERAGE(B16:F16) -> 2.6
A45: Kontakt til andre aktører | B45: =MAX(B17:F17) -> 2 | C45: =MIN(B17:F17) -> 1 | D45: =AVERAGE(B17:F17) -> 1.8
... A49: Åbenhed for at dele informationer | B49: =MAX(B21:F21) -> 3 | C49: =MIN(B21:F21) -> 0 | D49: =AVERAGE(B21:F21) -> 2.4

Sheet Score #1
A1: Kopier figuren til side 2 i parathedsrapporten (D. Skabelon-Rapport-1).

Sheet 1. Viden, kompetencer
A1: Kopier figuren til side 4 i parathedsrapporten (D. Skabelon-Rapport-1).

Sheet 2. Kultur, mindset
A1: Kopier figuren til side 5 i parathedsrapporten (D. Skabelon-Rapport-1).

Sheet 3. Værktøjer, mål, indikatorer
A1: Kopier figuren til side 6 i parathedsrapporten (D. Skabelon-Rapport-1).

Sheet 4. Netværk
A1: Kopier figuren til side 7 i parathedsrapporten (D. Skabelon-Rapport-1).

Sheet 5. B.samarbejde
A1: Kopier figuren til side 8 i parathedsrapporten (D. Skabelon-Rapport-1).

Sheet 6. Åbenhed
A1: Kopier figuren til side 9 i parathedsrapporten (D. Skabelon-Rapport-1).

Sheet Svarene #2
A1: Sæt virksomheds svar på spørgeskemaet #2 ind i tabellen nedenfor (0 - ved ikke/slet ikke, 1 - i mindre grad, 2 - i noget grad, 3 - i høj grad, 4 - i meget høj grad).
A3: Respondents: | B3: #1 | C3: #2 | D3: #3 | E3: #4 | F3: #5
A4: Questions / Positions: | B4: [indsæt medarbejders navn/titel] | C4: [indsæt medarbejders navn/titel] | D4: [indsæt medarbejders navn/titel] | E4: [indsæt medarbejders navn/titel] | F4: [indsæt medarbejders navn/titel]
A5: 1. Vi har medarbejdere med viden om bæredygtig udvikling | B5: 4 | C5: 4 | D5: 4 | E5: 3
A6: 2. Vi har en plan for at udvikle medarbejdernes viden og kompetencer mht. bæredygtighed og cirkulær økonomi | B6: 2 | C6: 1 | D6: 2 | E6: 2
A7: 3. Vi anser den grønne omstilling for en mulighed frem for en trussel | B7: 3 | C7: 3 | D7: 3 | E7: 2
A8: 4. Både vores ledelse og bestyrelse har fokus på bæredygtighed (f.eks. støtter de initiativer og projekter omkring bæredygtighed og allokerer ressourcer til dem) | B8: 3 | C8: 4 | D8: 3 | E8: 3
A9: 5. Mindset og kultur i vores organisation er fremadskuende og klar til at følge med den grønne omstilling | B9: 3 | C9: 3 | D9: 2 | E9: 2
A10: 6. Vi har værktøjer til at vurdere, hvilke effekter vores forretningsbeslutninger har på miljøet og samfundet | B10: 2 | C10: 2 | D10: 4 | E10: 2
A11: 7. Vores organisation har en klar strategi for at arbejde med bæredygtighed | B11: 3 | C11: 2 | D11: 5 | E11: 2
A12: 8. Vi har sat tydelige mål mht. bæredygtighed og bruger data og KPIer til at vurdere vores fremskridt | B12: 2 | C12: 2 | D12: 3 | E12: 2
B13: =AVERAGE(B5:F5)+AVERAGE(B6:F6)+AVERAGE(B7:F7)+AVERAGE(B8:F8)+AVERAGE(B9:F9)+AVERAGE(B10:F10)+AVERAGE(B11:F11)+AVERAGE(B12:F12) -> 21.75
A14: 9. Vi er gode til intern kommunikation og erfaringsudveksling | B14: 2 | C14: 2 | D14: 4 | E14: 2
A15: 10. Vi har gode kontakter i vores branche udenfor vores egen værdikæde (f.eks. er vi del af brancheorganisationer) | B15: 2 | C15: 3 | D15: 2 | E15: 2
A16: 11. Vi har god kontakt til virksomheder og andre aktører i vores lokalområde (f.eks. igennem lokale erhvervsnetværk) | B16: 3 | C16: 2 | D16: 4 | E16: 2
A17: 12. Vi har god kontakt til andre aktører (regeringen, universiteter, samfundsorganisationer og civilsamfundet) | B17: 2 | C17: 3 | D17: 3 | E17: 1
A18: 13. Vi arbejder sammen med og/eller påvirker vores værdikæde (f.eks. kunder og leverandører) mht. bæredygtighed | B18: 1 | C18: 4 | D18: 3 | E18: 3
A19: 14. Vi har allerede samarbejdet omkring bæredygtighed med aktørerne nævnt i spørgsmål 10-12 (f.eks. for at muliggøre cirkulære forretningsaktiviteter) | B19: 3 | C19: 3 | D19: 2 | E19: 2
A20: 15. Vi er åbne for nye partnerskaber omkring bæredygtighed | B20: 2 | C20: 4 | D20: 4 | E20: 4
A21: 16. Vi er klar til at dele informationer omkring vores forretning (f.eks. mængden af inputs og affaldsmaterialer) med andre organisationer | B21: 2 | C21: 4 | D21: 4 | E21: 3
B22: =AVERAGE(B14:F14)+AVERAGE(B15:F15)+AVERAGE(B16:F16)+AVERAGE(B17:F17)+AVERAGE(B18:F18)+AVERAGE(B19:F19)+AVERAGE(B20:F20)+AVERAGE(B21:F21) -> 21.75
B24: Score
A25: Bæredygtighed | B25: =B13 -> 21.75 | C25: -> indsæt værdien på side 2 i parathedsrapporten #2 (E. Skabelon-Rapport-2), linje 4
A26: Samarbejde | B26: =B22 -> 21.75 | C26: -> indsæt værdien på side 2 i parathedsrapporten #2 (E. Skabelon-Rapport-2), linje 5
A27: Total | B27: =B25+B26 -> 43.5 | C27: -> indsæt værdien på side 2 i parathedsrapporten #2 (E. Skabelon-Rapport-2), linje 2
A40: Bruges udelukkende for at automatisk generere grafikker i de andre ark.
B41: Før | C41: Nu
A42: Medarbejdere med viden om bæredygtig udvikling | B42: ='Svarene #1'!D33 -> 3.2 | C42: =AVERAGE(B5:F5) -> 3.75
A43: Plan for udvikling af viden og kompetencer | B43: ='Svarene #1'!D34 -> 1.8 | C43: =AVERAGE(B6:F6) -> 1.75
B44: Før | C44: Nu
A45: Grønne omstilling som mulighed | B45: ='Svarene #1'!D35 -> 2.8 | C45: =AVERAGE(B7:F7) -> 2.75
A46: Ledelse og bestyrelse med fokus på bæredygtighed | B46: ='Svarene #1'!D36 -> 2.6 | C46: =AVERAGE(B8:F8) -> 3.25
A47: Fremadskuende kultur og mindset | B47: ='Svarene #1'!D37 -> 2.8 | C47: =AVERAGE(B9:F9) -> 2.5
B48: Før | C48: Nu
A49: Værtøjer til effektvurdering | B49: ='Svarene #1'!D38 -> 1.4 | C49: =AVERAGE(B10:F10) -> 2.5
A50: Strategi | B50: ='Svarene #1'!D39 -> 2.8 | C50: =AVERAGE(B11:F11) -> 3
A51: Tydelige mål og KPIer | B51: ='Svarene #1'!D40 -> 1.2 | C51: =AVERAGE(B12:F12) -> 2.25
B52: Før | C52: Nu
A53: Intern kommunikation | B53: ='Svarene #1'!D42 -> 2.4 | C53: =AVERAGE(B14:F14) -> 2.5
A54: Kontakter i branchen | B54: ='Svarene #1'!D43 -> 1.8 | C54: =AVERAGE(B15:F15) -> 2.25
...

Sheet Score #2
A1: Kopier figuren til side 2 i parathedsrapporten #2 (E. Skabelon-Rapport-2).

Sheet 1. Viden, kompetencer #2
A1: Kopier figuren til side 4 i parathedsrapporten #2 (E. Skabelon-Rapport-2).

Sheet 2. Kultur, mindset #2
A1: Kopier figuren til side 5 i parathedsrapporten #2 (E. Skabelon-Rapport-2).

Sheet 3. Værktøjer, mål #2
A1: Kopier figuren til side 6 i parathedsrapporten #2 (E. Skabelon-Rapport-2).

Sheet 4. Netværk #2
A1: Kopier figuren til side 7 i parathedsrapporten #2 (E. Skabelon-Rapport-2).

Sheet 5. B.samarbejde #2
A1: Kopier figuren til side 8 i parathedsrapporten #2 (E. Skabelon-Rapport-2).

Sheet 6. Åbenhed #2
A1: Kopier figuren til side 9 i parathedsrapporten #2 (E. Skabelon-Rapport-2).
